2024-04-01 18:17:47,484 INFO    MainThread:4705 [wandb_setup.py:_flush():76] Current SDK version is 0.16.5
2024-04-01 18:17:47,485 INFO    MainThread:4705 [wandb_setup.py:_flush():76] Configure stats pid to 4705
2024-04-01 18:17:47,485 INFO    MainThread:4705 [wandb_setup.py:_flush():76] Loading settings from /Users/viditpokharna/.config/wandb/settings
2024-04-01 18:17:47,485 INFO    MainThread:4705 [wandb_setup.py:_flush():76] Loading settings from /Users/viditpokharna/Downloads/assignment-4/wandb/settings
2024-04-01 18:17:47,485 INFO    MainThread:4705 [wandb_setup.py:_flush():76] Loading settings from environment variables: {}
2024-04-01 18:17:47,485 INFO    MainThread:4705 [wandb_setup.py:_flush():76] Inferring run settings from compute environment: {'program': '<python with no main file>'}
2024-04-01 18:17:47,485 INFO    MainThread:4705 [wandb_setup.py:_flush():76] Applying login settings: {'api_key': '***REDACTED***'}
2024-04-01 18:17:47,485 INFO    MainThread:4705 [wandb_setup.py:_flush():76] Applying login settings: {'api_key': '***REDACTED***'}
2024-04-01 18:17:47,485 INFO    MainThread:4705 [wandb_setup.py:_flush():76] Applying login settings: {}
2024-04-01 18:17:47,485 INFO    MainThread:4705 [wandb_init.py:_log_setup():527] Logging user logs to /Users/viditpokharna/Downloads/assignment-4/wandb/run-20240401_181747-9d8geloa/logs/debug.log
2024-04-01 18:17:47,485 INFO    MainThread:4705 [wandb_init.py:_log_setup():528] Logging internal logs to /Users/viditpokharna/Downloads/assignment-4/wandb/run-20240401_181747-9d8geloa/logs/debug-internal.log
2024-04-01 18:17:47,485 INFO    MainThread:4705 [wandb_init.py:_jupyter_setup():473] configuring jupyter hooks <wandb.sdk.wandb_init._WandbInit object at 0x2ad3a67a0>
2024-04-01 18:17:47,485 INFO    MainThread:4705 [wandb_init.py:init():567] calling init triggers
2024-04-01 18:17:47,485 INFO    MainThread:4705 [wandb_init.py:init():574] wandb.init called with sweep_config: {}
config: {}
2024-04-01 18:17:47,485 INFO    MainThread:4705 [wandb_init.py:init():592] re-initializing run, found existing run on stack: njl0d3wu
2024-04-01 18:17:47,488 INFO    MainThread:4705 [wandb_run.py:_finish():2052] finishing run viditdpokharna/scene-recognition/njl0d3wu
2024-04-01 18:17:47,488 INFO    MainThread:4705 [wandb_run.py:_atexit_cleanup():2292] got exitcode: 0
2024-04-01 18:17:47,488 INFO    MainThread:4705 [wandb_run.py:_restore():2275] restore
2024-04-01 18:17:47,488 INFO    MainThread:4705 [wandb_run.py:_restore():2281] restore done
2024-04-01 18:17:52,535 INFO    MainThread:4705 [wandb_run.py:_footer_history_summary_info():3920] rendering history
2024-04-01 18:17:52,535 INFO    MainThread:4705 [wandb_run.py:_footer_history_summary_info():3952] rendering summary
2024-04-01 18:17:52,538 INFO    MainThread:4705 [wandb_run.py:_footer_sync_info():3879] logging synced files
2024-04-01 18:17:52,584 INFO    MainThread:4705 [wandb_init.py:init():617] starting backend
2024-04-01 18:17:52,584 INFO    MainThread:4705 [wandb_init.py:init():621] setting up manager
2024-04-01 18:17:52,587 INFO    MainThread:4705 [backend.py:_multiprocessing_setup():105] multiprocessing start_methods=spawn,fork,forkserver, using: spawn
2024-04-01 18:17:52,587 INFO    MainThread:4705 [wandb_init.py:init():629] backend started and connected
2024-04-01 18:17:52,596 INFO    MainThread:4705 [wandb_run.py:_label_probe_notebook():1299] probe notebook
2024-04-01 18:17:52,596 INFO    MainThread:4705 [wandb_run.py:_label_probe_notebook():1309] Unable to probe notebook: 'NoneType' object has no attribute 'get'
2024-04-01 18:17:52,596 INFO    MainThread:4705 [wandb_init.py:init():721] updated telemetry
2024-04-01 18:17:52,597 INFO    MainThread:4705 [wandb_init.py:init():754] communicating run to backend with 90.0 second timeout
2024-04-01 18:17:53,939 INFO    MainThread:4705 [wandb_run.py:_on_init():2344] communicating current version
2024-04-01 18:17:54,083 INFO    MainThread:4705 [wandb_run.py:_on_init():2353] got version response 
2024-04-01 18:17:54,083 INFO    MainThread:4705 [wandb_init.py:init():805] starting run threads in backend
2024-04-01 18:17:56,635 INFO    MainThread:4705 [wandb_run.py:_console_start():2323] atexit reg
2024-04-01 18:17:56,635 INFO    MainThread:4705 [wandb_run.py:_redirect():2178] redirect: wrap_raw
2024-04-01 18:17:56,635 INFO    MainThread:4705 [wandb_run.py:_redirect():2243] Wrapping output streams.
2024-04-01 18:17:56,636 INFO    MainThread:4705 [wandb_run.py:_redirect():2268] Redirects installed.
2024-04-01 18:17:56,636 INFO    MainThread:4705 [wandb_init.py:init():848] run started, returning control to user process
2024-04-01 18:28:45,016 WARNING MsgRouterThr:4705 [router.py:message_loop():77] message_loop has been closed
2024-04-01 18:35:05,770 INFO    MainThread:4705 [jupyter.py:save_ipynb():373] not saving jupyter notebook
2024-04-01 18:35:05,770 INFO    MainThread:4705 [wandb_init.py:_pause_backend():438] pausing backend
2024-04-01 21:43:44,611 INFO    MainThread:4705 [wandb_init.py:_resume_backend():443] resuming backend
2024-04-01 21:43:44,669 INFO    MainThread:4705 [wandb_setup.py:_flush():76] Current SDK version is 0.16.5
2024-04-01 21:43:44,669 INFO    MainThread:4705 [wandb_setup.py:_flush():76] Configure stats pid to 4705
2024-04-01 21:43:44,669 INFO    MainThread:4705 [wandb_setup.py:_flush():76] Loading settings from /Users/viditpokharna/.config/wandb/settings
2024-04-01 21:43:44,669 INFO    MainThread:4705 [wandb_setup.py:_flush():76] Loading settings from /Users/viditpokharna/Downloads/assignment-4/wandb/settings
2024-04-01 21:43:44,669 INFO    MainThread:4705 [wandb_setup.py:_flush():76] Loading settings from environment variables: {}
2024-04-01 21:43:44,669 INFO    MainThread:4705 [wandb_setup.py:_flush():76] Inferring run settings from compute environment: {'program': '<python with no main file>'}
2024-04-01 21:43:44,669 INFO    MainThread:4705 [wandb_setup.py:_flush():76] Applying login settings: {'api_key': '***REDACTED***'}
2024-04-01 21:43:44,669 INFO    MainThread:4705 [wandb_setup.py:_flush():76] Applying login settings: {'api_key': '***REDACTED***'}
2024-04-01 21:43:44,669 INFO    MainThread:4705 [wandb_setup.py:_flush():76] Applying login settings: {}
2024-04-01 21:43:44,669 INFO    MainThread:4705 [wandb_init.py:_log_setup():527] Logging user logs to /Users/viditpokharna/Downloads/assignment-4/wandb/run-20240401_214344-w1uj79ok/logs/debug.log
2024-04-01 21:43:44,669 INFO    MainThread:4705 [wandb_init.py:_log_setup():528] Logging internal logs to /Users/viditpokharna/Downloads/assignment-4/wandb/run-20240401_214344-w1uj79ok/logs/debug-internal.log
2024-04-01 21:43:44,669 INFO    MainThread:4705 [wandb_init.py:init():567] calling init triggers
2024-04-01 21:43:44,669 INFO    MainThread:4705 [wandb_init.py:init():574] wandb.init called with sweep_config: {}
config: {}
2024-04-01 21:43:44,669 INFO    MainThread:4705 [wandb_init.py:init():592] re-initializing run, found existing run on stack: 9d8geloa
2024-04-01 21:43:44,815 ERROR   MainThread:4705 [wandb_init.py:init():1215] error
Traceback (most recent call last):
  File "/Users/viditpokharna/anaconda3/envs/cv_proj4/lib/python3.10/site-packages/wandb/sdk/wandb_init.py", line 1187, in init
    run = wi.init()
  File "/Users/viditpokharna/anaconda3/envs/cv_proj4/lib/python3.10/site-packages/wandb/sdk/wandb_init.py", line 602, in init
    latest_run.finish()
  File "/Users/viditpokharna/anaconda3/envs/cv_proj4/lib/python3.10/site-packages/wandb/sdk/wandb_run.py", line 420, in wrapper
    return func(self, *args, **kwargs)
  File "/Users/viditpokharna/anaconda3/envs/cv_proj4/lib/python3.10/site-packages/wandb/sdk/wandb_run.py", line 361, in wrapper
    return func(self, *args, **kwargs)
  File "/Users/viditpokharna/anaconda3/envs/cv_proj4/lib/python3.10/site-packages/wandb/sdk/wandb_run.py", line 2043, in finish
    return self._finish(exit_code, quiet)
  File "/Users/viditpokharna/anaconda3/envs/cv_proj4/lib/python3.10/site-packages/wandb/sdk/wandb_run.py", line 2050, in _finish
    with telemetry.context(run=self) as tel:
  File "/Users/viditpokharna/anaconda3/envs/cv_proj4/lib/python3.10/site-packages/wandb/sdk/lib/telemetry.py", line 42, in __exit__
    self._run._telemetry_callback(self._obj)
  File "/Users/viditpokharna/anaconda3/envs/cv_proj4/lib/python3.10/site-packages/wandb/sdk/wandb_run.py", line 763, in _telemetry_callback
    self._telemetry_flush()
  File "/Users/viditpokharna/anaconda3/envs/cv_proj4/lib/python3.10/site-packages/wandb/sdk/wandb_run.py", line 774, in _telemetry_flush
    self._backend.interface._publish_telemetry(self._telemetry_obj)
  File "/Users/viditpokharna/anaconda3/envs/cv_proj4/lib/python3.10/site-packages/wandb/sdk/interface/interface_shared.py", line 101, in _publish_telemetry
    self._publish(rec)
  File "/Users/viditpokharna/anaconda3/envs/cv_proj4/lib/python3.10/site-packages/wandb/sdk/interface/interface_sock.py", line 51, in _publish
    self._sock_client.send_record_publish(record)
  File "/Users/viditpokharna/anaconda3/envs/cv_proj4/lib/python3.10/site-packages/wandb/sdk/lib/sock_client.py", line 221, in send_record_publish
    self.send_server_request(server_req)
  File "/Users/viditpokharna/anaconda3/envs/cv_proj4/lib/python3.10/site-packages/wandb/sdk/lib/sock_client.py", line 155, in send_server_request
    self._send_message(msg)
  File "/Users/viditpokharna/anaconda3/envs/cv_proj4/lib/python3.10/site-packages/wandb/sdk/lib/sock_client.py", line 152, in _send_message
    self._sendall_with_error_handle(header + data)
  File "/Users/viditpokharna/anaconda3/envs/cv_proj4/lib/python3.10/site-packages/wandb/sdk/lib/sock_client.py", line 130, in _sendall_with_error_handle
    sent = self._sock.send(data)
BrokenPipeError: [Errno 32] Broken pipe
2024-04-01 21:43:45,015 INFO    MainThread:4705 [jupyter.py:save_ipynb():373] not saving jupyter notebook
2024-04-01 21:43:45,015 INFO    MainThread:4705 [wandb_init.py:_pause_backend():438] pausing backend
2024-04-01 21:43:56,407 INFO    MainThread:4705 [wandb_init.py:_resume_backend():443] resuming backend
2024-04-01 21:43:56,436 ERROR   MainThread:4705 [wandb_init.py:init():1215] error
Traceback (most recent call last):
  File "/Users/viditpokharna/anaconda3/envs/cv_proj4/lib/python3.10/site-packages/wandb/sdk/wandb_init.py", line 1183, in init
    wi.setup(kwargs)
  File "/Users/viditpokharna/anaconda3/envs/cv_proj4/lib/python3.10/site-packages/wandb/sdk/wandb_init.py", line 226, in setup
    with telemetry.context(obj=self._init_telemetry_obj) as tel:
  File "/Users/viditpokharna/anaconda3/envs/cv_proj4/lib/python3.10/site-packages/wandb/sdk/lib/telemetry.py", line 42, in __exit__
    self._run._telemetry_callback(self._obj)
  File "/Users/viditpokharna/anaconda3/envs/cv_proj4/lib/python3.10/site-packages/wandb/sdk/wandb_run.py", line 763, in _telemetry_callback
    self._telemetry_flush()
  File "/Users/viditpokharna/anaconda3/envs/cv_proj4/lib/python3.10/site-packages/wandb/sdk/wandb_run.py", line 774, in _telemetry_flush
    self._backend.interface._publish_telemetry(self._telemetry_obj)
  File "/Users/viditpokharna/anaconda3/envs/cv_proj4/lib/python3.10/site-packages/wandb/sdk/interface/interface_shared.py", line 101, in _publish_telemetry
    self._publish(rec)
  File "/Users/viditpokharna/anaconda3/envs/cv_proj4/lib/python3.10/site-packages/wandb/sdk/interface/interface_sock.py", line 51, in _publish
    self._sock_client.send_record_publish(record)
  File "/Users/viditpokharna/anaconda3/envs/cv_proj4/lib/python3.10/site-packages/wandb/sdk/lib/sock_client.py", line 221, in send_record_publish
    self.send_server_request(server_req)
  File "/Users/viditpokharna/anaconda3/envs/cv_proj4/lib/python3.10/site-packages/wandb/sdk/lib/sock_client.py", line 155, in send_server_request
    self._send_message(msg)
  File "/Users/viditpokharna/anaconda3/envs/cv_proj4/lib/python3.10/site-packages/wandb/sdk/lib/sock_client.py", line 152, in _send_message
    self._sendall_with_error_handle(header + data)
  File "/Users/viditpokharna/anaconda3/envs/cv_proj4/lib/python3.10/site-packages/wandb/sdk/lib/sock_client.py", line 130, in _sendall_with_error_handle
    sent = self._sock.send(data)
BrokenPipeError: [Errno 32] Broken pipe
2024-04-01 21:43:56,559 INFO    MainThread:4705 [jupyter.py:save_ipynb():373] not saving jupyter notebook
2024-04-01 21:43:56,560 INFO    MainThread:4705 [wandb_init.py:_pause_backend():438] pausing backend
